Workbook

Sheet CLAIMS RAW DATA
A1: Claim_ID | B1: Patient_ID | C1: HMO Provider | D1: Hospital Branch | E1: Service Type | F1: Diagnosis Code | G1: Claim Date | H1: Approval Date | I1: Claim Amount | J1: Approved Amount | K1: Claim Status | L1: Rejection Reason | M1: Provider_ID | N1: Turnaround Days
A2: CLM00014 | B2: P0014 | C2: Leadway | D2: Apapa Branch | E2: Laboratory Test | F2: R73.0 | G2: 45475 | H2: 45479 | I2: 406921 | J2: 0 | K2: Rejected | L2: Service Not Covered | M2: PR003
A3: CLM00064 | B3: P0064 | C3: Hygeia | D3: Yaba Branch | E3: Maternity | F3: O80 | G3: 45298 | H3: 45302 | I3: 289828 | J3: 289828 | K3: approved | M3: PR011
A4: CLM00100 | B4: P0100 | C4: Hygeia | D4: Yaba Branch | E4: Outpatient Consultation | F4: E11.9 | G4: 45596 | H4: 45600 | J4: 520219 | K4: Partially Approved | M4: PR004
A5: CLM00271 | B5: P0271 | C5: AXA Mansard | D5: Lekki Branch | E5: Surgery | F5: K35.8 | G5: 45497 | H5: 45508 | I5: 623936 | J5: 623936 | K5: APPROVED | M5: PR012
A6: CLM00204 | B6: P0204 | C6: Leadway | D6: Lekki Branch | E6: Outpatient Consultation | F6: I10 | G6: 45647 | H6: 45658 | I6: 773168 | J6: 525502 | K6: Partially Approved | M6: PR012
A7: CLM00118 | B7: P0118 | C7: Hygeia | D7: Lekki Branch | E7: Diagnostic Imaging | F7: M54.5 | G7: 45337 | H7: 45349 | I7: 396857 | J7: 0 | K7: Rejected | L7: Policy Expired | M7: PR006
A8: CLM00107 | B8: P0107 | C8: AXA Mansard | D8: Surulere Branch | E8: Inpatient Admission | F8: I50.9 | G8: 45417 | H8: 45436 | I8: 935117 | J8: 935117 | K8: approved | M8: PR002
A9: CLM00239 | B9: P0239 | C9: Leadway | D9: Ikeja Branch | E9: Outpatient Consultation | F9: I10 | G9: 45536 | H9: 45544 | I9: 287193 | J9: 287193 | K9: APPROVED | M9: PR014
A10: CLM00108 | B10: P0108 | C10: Leadway | D10: Yaba Branch | E10: Inpatient Admission | F10: J44.1 | G10: 45561 | H10: 45576 | I10: 693062 | J10: 693062 | K10: Approved | M10: PR002
A11: CLM00111 | B11: P0111 | C11: NHIS | D11: Ikeja Branch | E11: Outpatient Consultation | F11: E11.9 | G11: 45597 | H11: 45601 | I11: 374686 | J11: 0 | K11: Rejected | L11: Incomplete Documentation | M11: PR003
A12: CLM00198 | B12: P0198 | C12: NHIS | D12: Lekki Branch | E12: Pharmacy | F12: E11.9 | G12: 45507 | K12: Pending | M12: PR014
A13: CLM00116 | B13: P0116 | C13: Leadway | D13: Ikeja Branch | E13: Pharmacy | F13: I10 | G13: 45621 | H13: 45628 | I13: 432645 | J13: 432645 | K13: APPROVED | M13: PR007
A14: CLM00167 | B14: P0167 | C14: AXA Mansard | D14: Ikeja Branch | E14: Diagnostic Imaging | F14: R91.8 | G14: 45435 | H14: 45437 | J14: 494451 | K14: approved | M14: PR014
A15: CLM00129 | B15: P0129 | C15: Leadway | D15: Yaba Branch | E15: Pharmacy | F15: E11.9 | G15: 45643 | I15: 239868 | K15: Pending | M15: PR006
A16: CLM00203 | B16: P0203 | C16: NHIS | D16: Ikeja Branch | E16: Pharmacy | F16: E11.9 | G16: 45403 | H16: 45413 | I16: 143233 | J16: 76796 | K16: Partially Approved | M16: PR004
A17: CLM00110 | B17: P0110 | C17: Hygeia | D17: Apapa Branch | E17: Inpatient Admission | F17: I50.9 | G17: 45482 | H17: 45502 | I17: 478930 | J17: 478930 | K17: Approved | M17: PR013
A18: CLM00179 | B18: P0179 | C18: Hygeia | D18: Lekki Branch | E18: Pharmacy | F18: I10 | G18: 45473 | I18: 249648 | K18: Pending | M18: PR007
A19: CLM00147 | B19: P0147 | C19: AXA Mansard | D19: Lekki Branch | E19: Inpatient Admission | F19: J44.1 | G19: 45459 | H19: 45479 | I19: 352513 | J19: 352513 | K19: approved | M19: PR015
A20: CLM00175 | B20: P0175 | C20: Leadway | D20: Apapa Branch | E20: Pharmacy | F20: E11.9 | G20: 45606 | H20: 45615 | I20: 272721 | J20: 272721 | K20: Approved | M20: PR001
A21: CLM00040 | B21: P0040 | C21: Leadway | D21: Lekki Branch | E21: Diagnostic Imaging | F21: R91.8 | G21: 45495 | H21: 45504 | I21: 178703 | J21: 142057 | K21: Partially Approved | M21: PR007
A22: CLM00196 | B22: P0196 | C22: Leadway | D22: Apapa Branch | E22: Pharmacy | F22: E11.9 | G22: 45548 | H22: 45554 | I22: 649455 | J22: 316948 | K22: Partially Approved | M22: PR012
A23: CLM00159 | B23: P0159 | C23: Leadway | D23: Lekki Branch | E23: Outpatient Consultation | F23: E11.9 | G23: 45333 | H23: 45337 | I23: 596518 | J23: 596518 | K23: APPROVED | M23: PR006
A24: CLM00209 | B24: P0209 | C24: Hygeia | D24: Apapa Branch | E24: Laboratory Test | F24: Z00.0 | G24: 45369 | H24: 45379 | I24: 331588 | J24: 0 | K24: Rejected | L24: Duplicate Claim | M24: PR004
A25: CLM00195 | B25: P0195 | C25: NHIS | D25: Ikeja Branch | E25: Surgery | F25: K35.8 | G25: 45571 | H25: 45576 | J25: 0 | K25: Rejected | L25: Incomplete Documentation | M25: PR004
A26: CLM00237 | B26: P0237 | C26: Hygeia | D26: Lekki Branch | E26: Inpatient Admission | F26: I50.9 | G26: 45605 | H26: 45618 | I26: 666971 | J26: 0 | K26: Rejected | L26: Service Not Covered | M26: PR004
A27: CLM00136 | B27: P0136 | C27: NHIS | D27: Lekki Branch | E27: Inpatient Admission | F27: N18.6 | G27: 45607 | H27: 45616 | I27: 445976 | J27: 0 | K27: Rejected | L27: Pre-authorisation Missing | M27: PR003
A28: CLM00223 | B28: P0223 | C28: AXA Mansard | D28: Lekki Branch | E28: Outpatient Consultation | F28: I10 | G28: 45472 | H28: 45474 | I28: 37135 | J28: 37135 | K28: APPROVED | M28: PR009
A29: CLM00255 | B29: P0255 | C29: Hygeia | D29: Surulere Branch | E29: Maternity | F29: O82 | G29: 45432 | H29: 45450 | I29: 784369 | J29: 784369 | K29: Approved | M29: PR008
A30: CLM00217 | B30: P0217 | C30: Leadway | D30: Yaba Branch | E30: Pharmacy | F30: E11.9 | G30: 45482 | H30: 45484 | I30: 833593 | J30: 0 | K30: Rejected | L30: Service Not Covered | M30: PR001
A31: CLM00155 | B31: P0155 | C31: Hygeia | D31: Apapa Branch | E31: Surgery | F31: K35.8 | G31: 45608 | H31: 45615 | I31: 835385 | J31: 0 | K31: Rejected | L31: Incomplete Documentation | M31: PR013
A32: CLM00050 | B32: P0050 | C32: Hygeia | D32: Surulere Branch | E32: Maternity | F32: O82 | G32: 45644 | H32: 45651 | I32: 367351 | J32: 367351 | K32: Approved | M32: PR012
A33: CLM00170 | B33: P0170 | C33: AXA Mansard | D33: Ikeja Branch | E33: Surgery | F33: K35.8 | G33: 45452 | H33: 45466 | I33: 110620 | J33: 110620 | K33: APPROVED | M33: PR007
A34: CLM00005 | B34: P0005 | C34: NHIS | D34: Lekki Branch | E34: Outpatient Consultation | F34: E11.9 | G34: 45584 | H34: 45586 | I34: 398487 | J34: 0 | K34: Rejected | L34: Policy Expired | M34: PR010
A35: CLM00173 | B35: P0173 | C35: AXA Mansard | D35: Lekki Branch | E35: Diagnostic Imaging | F35: R91.8 | G35: 45557 | H35: 45575 | I35: 486973 | J35: 486973 | K35: APPROVED | M35: PR008
A36: CLM00006 | B36: P0006 | C36: NHIS | D36: Apapa Branch | E36: Inpatient Admission | F36: N18.6 | G36: 45640 | H36: 45659 | I36: 496218 | J36: 496218 | K36: approved | M36: PR006
A37: CLM00033 | B37: P0033 | C37: Hygeia | D37: Surulere Branch | E37: Diagnostic Imaging | F37: M54.5 | G37: 45548 | H37: 45565 | J37: 556936 | K37: Approved | M37: PR008
A38: CLM00241 | B38: P0241 | C38: Hygeia | D38: Ikeja Branch | E38: Outpatient Consultation | F38: I10 | G38: 45417 | I38: 915513 | K38: Pending | M38: PR013
A39: CLM00186 | B39: P0186 | C39: Hygeia | D39: Lekki Branch | E39: Surgery | F39: S72.0 | G39: 45563 | H39: 45567 | I39: 711834 | J39: 711834 | K39: approved | M39: PR005
A40: CLM00162 | B40: P0162 | C40: Hygeia | D40: Ikeja Branch | E40: Laboratory Test | F40: R73.0 | G40: 45559 | H40: 45577 | I40: 702262 | J40: 702262 | K40: approved | M40: PR003
...

Sheet CLEANED CLAIMS
A1: Claim_ID | B1: Patient_ID | C1: HMO Provider | D1: Hospital Branch | E1: Service Type | F1: Diagnosis Code | G1: Claim Date | H1: Approval Date | I1: Claim Amount | J1: Approved Amount | K1: Claim Status | L1: Rejection Reason | M1: Provider_ID | N1: Turnaround Days | P1: Claim Amount Flag
A2: CLM00014 | B2: P0014 | C2: Leadway | D2: Apapa Branch | E2: Laboratory Test | F2: R73.0 | G2: 45475 | H2: 45479 | I2: 406921 | J2: 0 | K2: Rejected | L2: Service Not Covered | M2: PR003 | N2: =IF(H2="","Pending",H2-G2) -> 4 | P2: =IF(I2 = "", "Missing", "Recorded") -> Recorded
A3: CLM00064 | B3: P0064 | C3: Hygeia | D3: Yaba Branch | E3: Maternity | F3: O80 | G3: 45298 | H3: 45302 | I3: 289828 | J3: 289828 | K3: Approved | M3: PR011 | N3: =IF(H3="","Pending",H3-G3) -> 4 | P3: =IF(I3 = "", "Missing", "Recorded") -> Recorded
A4: CLM00100 | B4: P0100 | C4: Hygeia | D4: Yaba Branch | E4: Outpatient Consultation | F4: E11.9 | G4: 45596 | H4: 45600 | J4: 520219 | K4: Partially Approved | M4: PR004 | N4: =IF(H4="","Pending",H4-G4) -> 4 | P4: =IF(I4 = "", "Missing", "Recorded") -> Missing
A5: CLM00271 | B5: P0271 | C5: AXA Mansard | D5: Lekki Branch | E5: Surgery | F5: K35.8 | G5: 45497 | H5: 45508 | I5: 623936 | J5: 623936 | K5: Approved | M5: PR012 | N5: =IF(H5="","Pending",H5-G5) -> 11 | P5: =IF(I5 = "", "Missing", "Recorded") -> Recorded
A6: CLM00204 | B6: P0204 | C6: Leadway | D6: Lekki Branch | E6: Outpatient Consultation | F6: I10 | G6: 45647 | H6: 45658 | I6: 773168 | J6: 525502 | K6: Partially Approved | M6: PR012 | N6: =IF(H6="","Pending",H6-G6) -> 11 | P6: =IF(I6 = "", "Missing", "Recorded") -> Recorded | R6: HMO Provider | S6: Rejected Count | T6: Total Claims | U6: Rejection Rate | V6: Rejection Reason | W6: count | Z6: Rejection Reason | AC6: Avg turnaround days | AE6: hospital branch | AF6: total Claim Value | AI6: service type | AJ6: avg claim amount
A7: CLM00118 | B7: P0118 | C7: Hygeia | D7: Lekki Branch | E7: Diagnostic Imaging | F7: M54.5 | G7: 45337 | H7: 45349 | I7: 396857 | J7: 0 | K7: Rejected | L7: Policy Expired | M7: PR006 | N7: =IF(H7="","Pending",H7-G7) -> 12 | P7: =IF(I7 = "", "Missing", "Recorded") -> Recorded | R7: NHIS | S7: =COUNTIFS($C$2:$C$301,R7,$K$2:$K$301,"Rejected") -> 17 | T7: =COUNTIF(C:C,R7) -> 98 | U7: =S7/T7*100 -> 17.346939 | V7: Duplicate Claim | W7: =COUNTIF(L:L,V7) -> 5 | Z7: Duplicate Claim | AA7: =COUNTIFS($C$2:$C$301,"Leadway",$L$2:$L$301,Z7) -> 0 | AC7: =AVERAGEIF($C$2:$C$301,R7,$N$2:$N$301) -> 11.287356 | AE7: Lekki Branch | AF7: =SUMIF($D$2:$D$301,AE7,$I$2:$I$301) -> 28818989 | AG7: =COUNTIFS($D$2:$D$301,AE7,$P$2:$P$301,"Missing") -> 5 | AI7: Laboratory Test | AJ7: =AVERAGEIF($E$2:$E$301,AI7,$I$2:$I$301) -> 549240.29
A8: CLM00107 | B8: P0107 | C8: AXA Mansard | D8: Surulere Branch | E8: Inpatient Admission | F8: I50.9 | G8: 45417 | H8: 45436 | I8: 935117 | J8: 935117 | K8: Approved | M8: PR002 | N8: =IF(H8="","Pending",H8-G8) -> 19 | P8: =IF(I8 = "", "Missing", "Recorded") -> Recorded | R8: AXA Mansard | S8: =COUNTIFS($C$2:$C$301,R8,$K$2:$K$301,"Rejected") -> 10 | T8: =COUNTIF(C:C,R8) -> 55 | U8: =S8/T8*100 -> 18.181818 | V8: Incomplete Documentation | W8: =COUNTIF(L:L,V8) -> 13 | Z8: Incomplete Documentation | AA8: =COUNTIFS($C$2:$C$301,"Leadway",$L$2:$L$301,Z8) -> 2 | AC8: =AVERAGEIF($C$2:$C$301,R8,$N$2:$N$301) -> 9.4117647 | AE8: Yaba Branch | AF8: =SUMIF($D$2:$D$301,AE8,$I$2:$I$301) -> 25611599 | AG8: =COUNTIFS($D$2:$D$301,AE8,$P$2:$P$301,"Missing") -> 4 | AI8: Maternity | AJ8: =AVERAGEIF($E$2:$E$301,AI8,$I$2:$I$301) -> 508253.41
A9: CLM00239 | B9: P0239 | C9: Leadway | D9: Ikeja Branch | E9: Outpatient Consultation | F9: I10 | G9: 45536 | H9: 45544 | I9: 287193 | J9: 287193 | K9: Approved | M9: PR014 | N9: =IF(H9="","Pending",H9-G9) -> 8 | P9: =IF(I9 = "", "Missing", "Recorded") -> Recorded | R9: Hygeia | S9: =COUNTIFS($C$2:$C$301,R9,$K$2:$K$301,"Rejected") -> 17 | T9: =COUNTIF(C:C,R9) -> 97 | U9: =S9/T9*100 -> 17.525773 | V9: Service Not Covered | W9: =COUNTIF(L:L,V9) -> 13 | Z9: Service Not Covered | AA9: =COUNTIFS($C$2:$C$301,"Leadway",$L$2:$L$301,Z9) -> 6 | AC9: =AVERAGEIF($C$2:$C$301,R9,$N$2:$N$301) -> 11.686747 | AE9: Apapa Branch | AF9: =SUMIF($D$2:$D$301,AE9,$I$2:$I$301) -> 21370061 | AG9: =COUNTIFS($D$2:$D$301,AE9,$P$2:$P$301,"Missing") -> 2 | AI9: Surgery | AJ9: =AVERAGEIF($E$2:$E$301,AI9,$I$2:$I$301) -> 445349.02
A10: CLM00108 | B10: P0108 | C10: Leadway | D10: Yaba Branch | E10: Inpatient Admission | F10: J44.1 | G10: 45561 | H10: 45576 | I10: 693062 | J10: 693062 | K10: Approved | M10: PR002 | N10: =IF(H10="","Pending",H10-G10) -> 15 | P10: =IF(I10 = "", "Missing", "Recorded") -> Recorded | R10: Leadway | S10: =COUNTIFS($C$2:$C$301,R10,$K$2:$K$301,"Rejected") -> 12 | T10: =COUNTIF(C:C,R10) -> 50 | U10: =S10/T10*100 -> 24 | V10: Pre-authorisation Missing | W10: =COUNTIF(L:L,V10) -> 12 | Z10: Pre-authorisation Missing | AA10: =COUNTIFS($C$2:$C$301,"Leadway",$L$2:$L$301,Z10) -> 1 | AC10: =AVERAGEIF($C$2:$C$301,R10,$N$2:$N$301) -> 9.4761905 | AE10: Ikeja Branch | AF10: =SUMIF($D$2:$D$301,AE10,$I$2:$I$301) -> 25648568 | AG10: =COUNTIFS($D$2:$D$301,AE10,$P$2:$P$301,"Missing") -> 5 | AI10: Outpatient Consultation | AJ10: =AVERAGEIF($E$2:$E$301,AI10,$I$2:$I$301) -> 417478.31
A11: CLM00111 | B11: P0111 | C11: NHIS | D11: Ikeja Branch | E11: Outpatient Consultation | F11: E11.9 | G11: 45597 | H11: 45601 | I11: 374686 | J11: 0 | K11: Rejected | L11: Incomplete Documentation | M11: PR003 | N11: =IF(H11="","Pending",H11-G11) -> 4 | P11: =IF(I11 = "", "Missing", "Recorded") -> Recorded | S11: =SUM(S7:S10) -> 56 | T11: =SUM(T7:T10) -> 300 | V11: Policy Expired | W11: =COUNTIF(L:L,V11) -> 13 | Z11: Policy Expired | AA11: =COUNTIFS($C$2:$C$301,"Leadway",$L$2:$L$301,Z11) -> 3 | AE11: Surulere Branch | AF11: =SUMIF($D$2:$D$301,AE11,$I$2:$I$301) -> 26118898 | AG11: =COUNTIFS($D$2:$D$301,AE11,$P$2:$P$301,"Missing") -> 4 | AI11: Diagnostic Imaging | AJ11: =AVERAGEIF($E$2:$E$301,AI11,$I$2:$I$301) -> 409417.78
A12: CLM00198 | B12: P0198 | C12: NHIS | D12: Lekki Branch | E12: Pharmacy | F12: E11.9 | G12: 45507 | K12: Pending | M12: PR014 | N12: =IF(H12="","Pending",H12-G12) -> Pending | P12: =IF(I12 = "", "Missing", "Recorded") -> Missing | W12: =SUM(W7:W11) -> 56 | AA12: =SUM(AA7:AA11) -> 12 | AF12: =SUM(AF7:AF11) -> 127568115 | AI12: Inpatient Admission | AJ12: =AVERAGEIF($E$2:$E$301,AI12,$I$2:$I$301) -> 451575.23
A13: CLM00116 | B13: P0116 | C13: Leadway | D13: Ikeja Branch | E13: Pharmacy | F13: I10 | G13: 45621 | H13: 45628 | I13: 432645 | J13: 432645 | K13: Approved | M13: PR007 | N13: =IF(H13="","Pending",H13-G13) -> 7 | P13: =IF(I13 = "", "Missing", "Recorded") -> Recorded | AI13: Pharmacy | AJ13: =AVERAGEIF($E$2:$E$301,AI13,$I$2:$I$301) -> 449372.89
A14: CLM00167 | B14: P0167 | C14: AXA Mansard | D14: Ikeja Branch | E14: Diagnostic Imaging | F14: R91.8 | G14: 45435 | H14: 45437 | J14: 494451 | K14: Approved | M14: PR014 | N14: =IF(H14="","Pending",H14-G14) -> 2 | P14: =IF(I14 = "", "Missing", "Recorded") -> Missing
A15: CLM00129 | B15: P0129 | C15: Leadway | D15: Yaba Branch | E15: Pharmacy | F15: E11.9 | G15: 45643 | I15: 239868 | K15: Pending | M15: PR006 | N15: =IF(H15="","Pending",H15-G15) -> Pending | P15: =IF(I15 = "", "Missing", "Recorded") -> Recorded
A16: CLM00203 | B16: P0203 | C16: NHIS | D16: Ikeja Branch | E16: Pharmacy | F16: E11.9 | G16: 45403 | H16: 45413 | I16: 143233 | J16: 76796 | K16: Partially Approved | M16: PR004 | N16: =IF(H16="","Pending",H16-G16) -> 10 | P16: =IF(I16 = "", "Missing", "Recorded") -> Recorded
A17: CLM00110 | B17: P0110 | C17: Hygeia | D17: Apapa Branch | E17: Inpatient Admission | F17: I50.9 | G17: 45482 | H17: 45502 | I17: 478930 | J17: 478930 | K17: Approved | M17: PR013 | N17: =IF(H17="","Pending",H17-G17) -> 20 | P17: =IF(I17 = "", "Missing", "Recorded") -> Recorded
A18: CLM00179 | B18: P0179 | C18: Hygeia | D18: Lekki Branch | E18: Pharmacy | F18: I10 | G18: 45473 | I18: 249648 | K18: Pending | M18: PR007 | N18: =IF(H18="","Pending",H18-G18) -> Pending | P18: =IF(I18 = "", "Missing", "Recorded") -> Recorded
A19: CLM00147 | B19: P0147 | C19: AXA Mansard | D19: Lekki Branch | E19: Inpatient Admission | F19: J44.1 | G19: 45459 | H19: 45479 | I19: 352513 | J19: 352513 | K19: Approved | M19: PR015 | N19: =IF(H19="","Pending",H19-G19) -> 20 | P19: =IF(I19 = "", "Missing", "Recorded") -> Recorded
A20: CLM00175 | B20: P0175 | C20: Leadway | D20: Apapa Branch | E20: Pharmacy | F20: E11.9 | G20: 45606 | H20: 45615 | I20: 272721 | J20: 272721 | K20: Approved | M20: PR001 | N20: =IF(H20="","Pending",H20-G20) -> 9 | P20: =IF(I20 = "", "Missing", "Recorded") -> Recorded
A21: CLM00040 | B21: P0040 | C21: Leadway | D21: Lekki Branch | E21: Diagnostic Imaging | F21: R91.8 | G21: 45495 | H21: 45504 | I21: 178703 | J21: 142057 | K21: Partially Approved | M21: PR007 | N21: =IF(H21="","Pending",H21-G21) -> 9 | P21: =IF(I21 = "", "Missing", "Recorded") -> Recorded
A22: CLM00196 | B22: P0196 | C22: Leadway | D22: Apapa Branch | E22: Pharmacy | F22: E11.9 | G22: 45548 | H22: 45554 | I22: 649455 | J22: 316948 | K22: Partially Approved | M22: PR012 | N22: =IF(H22="","Pending",H22-G22) -> 6 | P22: =IF(I22 = "", "Missing", "Recorded") -> Recorded
A23: CLM00159 | B23: P0159 | C23: Leadway | D23: Lekki Branch | E23: Outpatient Consultation | F23: E11.9 | G23: 45333 | H23: 45337 | I23: 596518 | J23: 596518 | K23: Approved | M23: PR006 | N23: =IF(H23="","Pending",H23-G23) -> 4 | P23: =IF(I23 = "", "Missing", "Recorded") -> Recorded
A24: CLM00209 | B24: P0209 | C24: Hygeia | D24: Apapa Branch | E24: Laboratory Test | F24: Z00.0 | G24: 45369 | H24: 45379 | I24: 331588 | J24: 0 | K24: Rejected | L24: Duplicate Claim | M24: PR004 | N24: =IF(H24="","Pending",H24-G24) -> 10 | P24: =IF(I24 = "", "Missing", "Recorded") -> Recorded
A25: CLM00195 | B25: P0195 | C25: NHIS | D25: Ikeja Branch | E25: Surgery | F25: K35.8 | G25: 45571 | H25: 45576 | J25: 0 | K25: Rejected | L25: Incomplete Documentation | M25: PR004 | N25: =IF(H25="","Pending",H25-G25) -> 5 | P25: =IF(I25 = "", "Missing", "Recorded") -> Missing
A26: CLM00237 | B26: P0237 | C26: Hygeia | D26: Lekki Branch | E26: Inpatient Admission | F26: I50.9 | G26: 45605 | H26: 45618 | I26: 666971 | J26: 0 | K26: Rejected | L26: Service Not Covered | M26: PR004 | N26: =IF(H26="","Pending",H26-G26) -> 13 | P26: =IF(I26 = "", "Missing", "Recorded") -> Recorded
A27: CLM00136 | B27: P0136 | C27: NHIS | D27: Lekki Branch | E27: Inpatient Admission | F27: N18.6 | G27: 45607 | H27: 45616 | I27: 445976 | J27: 0 | K27: Rejected | L27: Pre-authorisation Missing | M27: PR003 | N27: =IF(H27="","Pending",H27-G27) -> 9 | P27: =IF(I27 = "", "Missing", "Recorded") -> Recorded
A28: CLM00223 | B28: P0223 | C28: AXA Mansard | D28: Lekki Branch | E28: Outpatient Consultation | F28: I10 | G28: 45472 | H28: 45474 | I28: 37135 | J28: 37135 | K28: Approved | M28: PR009 | N28: =IF(H28="","Pending",H28-G28) -> 2 | P28: =IF(I28 = "", "Missing", "Recorded") -> Recorded
A29: CLM00255 | B29: P0255 | C29: Hygeia | D29: Surulere Branch | E29: Maternity | F29: O82 | G29: 45432 | H29: 45450 | I29: 784369 | J29: 784369 | K29: Approved | M29: PR008 | N29: =IF(H29="","Pending",H29-G29) -> 18 | P29: =IF(I29 = "", "Missing", "Recorded") -> Recorded
A30: CLM00217 | B30: P0217 | C30: Leadway | D30: Yaba Branch | E30: Pharmacy | F30: E11.9 | G30: 45482 | H30: 45484 | I30: 833593 | J30: 0 | K30: Rejected | L30: Service Not Covered | M30: PR001 | N30: =IF(H30="","Pending",H30-G30) -> 2 | P30: =IF(I30 = "", "Missing", "Recorded") -> Recorded
A31: CLM00155 | B31: P0155 | C31: Hygeia | D31: Apapa Branch | E31: Surgery | F31: K35.8 | G31: 45608 | H31: 45615 | I31: 835385 | J31: 0 | K31: Rejected | L31: Incomplete Documentation | M31: PR013 | N31: =IF(H31="","Pending",H31-G31) -> 7 | P31: =IF(I31 = "", "Missing", "Recorded") -> Recorded
A32: CLM00050 | B32: P0050 | C32: Hygeia | D32: Surulere Branch | E32: Maternity | F32: O82 | G32: 45644 | H32: 45651 | I32: 367351 | J32: 367351 | K32: Approved | M32: PR012 | N32: =IF(H32="","Pending",H32-G32) -> 7 | P32: =IF(I32 = "", "Missing", "Recorded") -> Recorded
A33: CLM00170 | B33: P0170 | C33: AXA Mansard | D33: Ikeja Branch | E33: Surgery | F33: K35.8 | G33: 45452 | H33: 45466 | I33: 110620 | J33: 110620 | K33: Approved | M33: PR007 | N33: =IF(H33="","Pending",H33-G33) -> 14 | P33: =IF(I33 = "", "Missing", "Recorded") -> Recorded
A34: CLM00005 | B34: P0005 | C34: NHIS | D34: Lekki Branch | E34: Outpatient Consultation | F34: E11.9 | G34: 45584 | H34: 45586 | I34: 398487 | J34: 0 | K34: Rejected | L34: Policy Expired | M34: PR010 | N34: =IF(H34="","Pending",H34-G34) -> 2 | P34: =IF(I34 = "", "Missing", "Recorded") -> Recorded
A35: CLM00173 | B35: P0173 | C35: AXA Mansard | D35: Lekki Branch | E35: Diagnostic Imaging | F35: R91.8 | G35: 45557 | H35: 45575 | I35: 486973 | J35: 486973 | K35: Approved | M35: PR008 | N35: =IF(H35="","Pending",H35-G35) -> 18 | P35: =IF(I35 = "", "Missing", "Recorded") -> Recorded
A36: CLM00006 | B36: P0006 | C36: NHIS | D36: Apapa Branch | E36: Inpatient Admission | F36: N18.6 | G36: 45640 | H36: 45659 | I36: 496218 | J36: 496218 | K36: Approved | M36: PR006 | N36: =IF(H36="","Pending",H36-G36) -> 19 | P36: =IF(I36 = "", "Missing", "Recorded") -> Recorded
A37: CLM00033 | B37: P0033 | C37: Hygeia | D37: Surulere Branch | E37: Diagnostic Imaging | F37: M54.5 | G37: 45548 | H37: 45565 | J37: 556936 | K37: Approved | M37: PR008 | N37: =IF(H37="","Pending",H37-G37) -> 17 | P37: =IF(I37 = "", "Missing", "Recorded") -> Missing
A38: CLM00241 | B38: P0241 | C38: Hygeia | D38: Ikeja Branch | E38: Outpatient Consultation | F38: I10 | G38: 45417 | I38: 915513 | K38: Pending | M38: PR013 | N38: =IF(H38="","Pending",H38-G38) -> Pending | P38: =IF(I38 = "", "Missing", "Recorded") -> Recorded
A39: CLM00186 | B39: P0186 | C39: Hygeia | D39: Lekki Branch | E39: Surgery | F39: S72.0 | G39: 45563 | H39: 45567 | I39: 711834 | J39: 711834 | K39: Approved | M39: PR005 | N39: =IF(H39="","Pending",H39-G39) -> 4 | P39: =IF(I39 = "", "Missing", "Recorded") -> Recorded
A40: CLM00162 | B40: P0162 | C40: Hygeia | D40: Ikeja Branch | E40: Laboratory Test | F40: R73.0 | G40: 45559 | H40: 45577 | I40: 702262 | J40: 702262 | K40: Approved | M40: PR003 | N40: =IF(H40="","Pending",H40-G40) -> 18 | P40: =IF(I40 = "", "Missing", "Recorded") -> Recorded
...

Sheet BUSINESS QUESTIONS
A1: PROJECT 1 — Health Insurance Claims Analysis
A2: No step-by-step instructions this time. Clean the data, then answer every question below independently.
B4: DATA CLEANING
B5: 1. Identify and remove duplicate claims using Claim_ID.
B6: 2. Standardise Claim Status to exactly 4 categories: Approved, Rejected, Pending, Partially Approved.
B7: 3. Calculate Turnaround Days = Approval Date − Claim Date (leave blank where Approval Date is missing).
B8: 4. Flag claims with missing Claim Amount instead of deleting them.
B10: ANALYSIS QUESTIONS
B11: 5. What is the overall claim approval rate (Approved + Partially Approved ÷ Total)?
B12: 6. Which HMO provider has the highest rejection rate?
B13: 7. What is the most common rejection reason overall, and per HMO?
B14: 8. What is the average turnaround time (claim to approval) by HMO provider?
B15: 9. Which hospital branch submits the highest total claim value?
B16: 10. Which service type has the highest average claim amount?
... B28: Package this project for GitHub using the structure: README.md + raw_data.xlsx + cleaned_data.xlsx + dashboard screenshot.

Sheet pivot table 1
A3: Row Labels | B3: Sum of Claim Amount | C3: Sum of Approved Amount
A4: AXA Mansard | B4: 22529653 | C4: 16563407 | D4: =C4/B4*100 -> 73.518252
A5: Hygeia | B5: 39007046 | C5: 26404020 | D5: =C5/B5*100 -> 67.690386
A6: Leadway | B6: 20560132 | C6: 13245722 | D6: =C6/B6*100 -> 64.424304
A7: NHIS | B7: 45471284 | C7: 30441067 | D7: =C7/B7*100 -> 66.945695
A8: Grand Total | B8: 127568115 | C8: 86654216

Sheet pivot table 2
A3: Row Labels | B3: Count of Claim_ID
A4: Jan | B4: 28
A5: Feb | B5: 24
A6: Mar | B6: 22
A7: Apr | B7: 15
A8: May | B8: 28
A9: Jun | B9: 29
A10: Jul | B10: 36
A11: Aug | B11: 23
A12: Sep | B12: 26
A13: Oct | B13: 20
A14: Nov | B14: 25
A15: Dec | B15: 24
A16: Grand Total | B16: 300

Sheet DASHBOARD
B2: HMO Provider | C2: Approval Rate % | E2: Rejection Reason | F2: Count | H2: Row Labels | I2: Count of Claim_ID
B3: NHIS | C3: =(COUNTIFS('CLEANED CLAIMS'!$C$2:$C$301,B3,'CLEANED CLAIMS'!$K$2:$K$301,"Approved")+COUNTIFS('CLEANED CLAIMS'!$C$2:$C$301,B3,'CLEANED CLAIMS'!$K$2:$K$301,"Partially Approved"))/COUNTIF('CLEANED CLAIMS'!$C$2:$C$301,B3)*100 -> 71.428571 | E3: Duplicate Claim | F3: =COUNTIF('CLEANED CLAIMS'!$L$2:$L$301,E3) -> 5 | H3: Jan | I3: 28
B4: AXA Mansard | C4: =(COUNTIFS('CLEANED CLAIMS'!$C$2:$C$301,B4,'CLEANED CLAIMS'!$K$2:$K$301,"Approved")+COUNTIFS('CLEANED CLAIMS'!$C$2:$C$301,B4,'CLEANED CLAIMS'!$K$2:$K$301,"Partially Approved"))/COUNTIF('CLEANED CLAIMS'!$C$2:$C$301,B4)*100 -> 74.545455 | E4: Incomplete Documentation | F4: =COUNTIF('CLEANED CLAIMS'!$L$2:$L$301,E4) -> 13 | H4: Feb | I4: 24
B5: Hygeia | C5: =(COUNTIFS('CLEANED CLAIMS'!$C$2:$C$301,B5,'CLEANED CLAIMS'!$K$2:$K$301,"Approved")+COUNTIFS('CLEANED CLAIMS'!$C$2:$C$301,B5,'CLEANED CLAIMS'!$K$2:$K$301,"Partially Approved"))/COUNTIF('CLEANED CLAIMS'!$C$2:$C$301,B5)*100 -> 68.041237 | E5: Service Not Covered | F5: =COUNTIF('CLEANED CLAIMS'!$L$2:$L$301,E5) -> 13 | H5: Mar | I5: 22
B6: Leadway | C6: =(COUNTIFS('CLEANED CLAIMS'!$C$2:$C$301,B6,'CLEANED CLAIMS'!$K$2:$K$301,"Approved")+COUNTIFS('CLEANED CLAIMS'!$C$2:$C$301,B6,'CLEANED CLAIMS'!$K$2:$K$301,"Partially Approved"))/COUNTIF('CLEANED CLAIMS'!$C$2:$C$301,B6)*100 -> 60 | E6: Pre-authorisation Missing | F6: =COUNTIF('CLEANED CLAIMS'!$L$2:$L$301,E6) -> 12 | H6: Apr | I6: 15
E7: Policy Expired | F7: =COUNTIF('CLEANED CLAIMS'!$L$2:$L$301,E7) -> 13 | H7: May | I7: 28
H8: Jun | I8: 29
H9: Jul | I9: 36
H10: Aug | I10: 23
H11: Sep | I11: 26
H12: Oct | I12: 20
H13: Nov | I13: 25
H14: Dec | I14: 24
